Workbook
Name feladvany_lista: 'Segéd'!$E$2:$E$43

Sheet Útmutató
A1: Rokonszavak – feladványbank és gyakorlólap
A3: Feladványok lap – ide írod az adatokat. Minden sor egy csoport, minden feladvány 4 sor (szint 1–4).
A4: Játék lap – itt tudod magad megfejteni. Csak a sárga cellát állítod (B2), a többi képlet.
A5: Segéd lap – rejtett, a keverést tárolja. Ne szerkeszd.
A7: Új feladvány felvétele: írj 4 új sort a Feladványok lap aljára, azonos feladvany_id-vel és kezdes dátummal, szint 1-től 4-ig.
A8: Szabályok: 16 egyedi szó feladványonként, szint 1 a legkönnyebb, szint 4 a legnehezebb.
A9: Szóhossz: 9 karakterig biztosan elfér egy sorban. 10–12 karakter csak kétsoros dobozzal, feladványonként legfeljebb egy ilyen szó.
A10: NINCS kakukktojás: egy szó sem illhet két csoportba ugyanabban a feladványban. A nehézséget a kategória adja, nem a kétértelműség.
A11: A megjegyzes oszlop a játékosnak szól. Az ellenorzes oszlop csak neked – ez sosem kerül ki a weboldalra.
A17: ÚJ SZABÁLY: egy csoporton belül ne végződjön három szó ugyanúgy (pl. mind -usz vagy mind -on). A közös végződés ránézésre megadja a csoportot.
A18: ÚJ SZABÁLY: ne legyen sok tulajdonneves csoport, és ritkán térjen vissza az "amit lehet X-ni" meg a "___ + SZÓ" típus.
A19: A megjegyzes oszlopba csak akkor írj, ha tényleg hoz új infót (teljes név, rövidítés feloldása, ritka szó jelentése). Ami a kategórianévből amúgy is kiderül, azt hagyd üresen.
... A23: Figyelem: rsz-040 "Terjedelem" szava 10 karakter - kétsoros doboz kell hozzá.

Sheet Feladványok
A1: feladvany_id | B1: kezdes | C1: szint | D1: kategoria | E1: megjegyzes | F1: szo1 | G1: szo2 | H1: szo3 | I1: szo4 | J1: ellenorzes_regi | K1: ellenorzes
A2: rsz-002 | B2: 2026-09-24 | C2: 1 | D2: Magyar levesek | F2: Palóc | G2: Jókai | H2: Újházi | I2: Gulyás
A3: rsz-002 | B3: 2026-09-24 | C3: 2 | D3: Budapesti hidak | F3: Lánc | G3: Erzsébet | H3: Margit | I3: Szabadság
A4: rsz-002 | B4: 2026-09-24 | C4: 3 | D4: Foglalkozás és gyakori vezetéknév | F4: Kovács | G4: Szabó | H4: Molnár | I4: Halász | J4: Gulyás (foglalkozás és vezetéknév is)
A5: rsz-002 | B5: 2026-09-24 | C5: 4 | D5: Amit le lehet tenni | F5: Vizsga | G5: Eskü | H5: Fegyver | I5: Lant
A6: rsz-003 | B6: 2026-09-25 | C6: 1 | D6: Csillagjegyek | F6: Rák | G6: Kos | H6: Bika | I6: Ikrek
A7: rsz-003 | B7: 2026-09-25 | C7: 2 | D7: Magyar kutyafajták | F7: Puli | G7: Vizsla | H7: Kuvasz | I7: Pumi
A8: rsz-003 | B8: 2026-09-25 | C8: 3 | D8: Aminek nyelve van | F8: Cipő | G8: Harang | H8: Öv | I8: Mérleg | J8: Mérleg (csillagjegy is)
A9: rsz-003 | B9: 2026-09-25 | C9: 4 | D9: Egy betű cseréjével vármegye | E9: Fejér, Békés, Pest, Tolna | F9: Fehér | G9: Bélés | H9: Rest | I9: Volna
A10: rsz-004 | B10: 2026-09-26 | C10: 1 | D10: Magyar kártya színei | F10: Makk | G10: Tök | H10: Zöld | I10: Piros
A11: rsz-004 | B11: 2026-09-26 | C11: 2 | D11: Pálinkafajták | F11: Barack | G11: Szilva | H11: Törköly | I11: Kökény
A12: rsz-004 | B12: 2026-09-26 | C12: 3 | D12: Ételnév, ami személynévből jön | E12: Dobos C. József, Rigó Jancsi, Esterházy Pál, Gerbeaud Emil | F12: Dobos | G12: Rigó | H12: Esterházy | I12: Zserbó
A13: rsz-004 | B13: 2026-09-26 | C13: 4 | D13: Amit el lehet sütni | F13: Poén | G13: Puska | H13: Vicc | I13: Ágyú
A14: rsz-005 | B14: 2026-09-27 | C14: 1 | D14: Magyar rajzfilmfigurák | F14: Vuk | G14: Süsü | H14: Frakk | I14: Kukori
A15: rsz-005 | B15: 2026-09-27 | C15: 2 | D15: ___ + ÓRA | F15: Nap | G15: Homok | H15: Inga | I15: Torony
A16: rsz-005 | B16: 2026-09-27 | C16: 3 | D16: Keresztnévvel kezdődik | E16: Kata, Lili, Andor, Ferenc | F16: Katapult | G16: Liliom | H16: Andorra | I16: Ferences
A17: rsz-005 | B17: 2026-09-27 | C17: 4 | D17: Visszafelé olvasva is magyar szó | E17: rak, pék, tál, rét | F17: Kar | G17: Kép | H17: Lát | I17: Tér | J17: Kar (karóra)
A18: rsz-006 | B18: 2026-09-28 | C18: 1 | D18: Sakkfigurák | F18: Bástya | G18: Futó | H18: Huszár | I18: Vezér
A19: rsz-006 | B19: 2026-09-28 | C19: 2 | D19: Magyar folyók | F19: Tisza | G19: Dráva | H19: Rába | I19: Sajó
A20: rsz-006 | B20: 2026-09-28 | C20: 3 | D20: Amit fel lehet venni | F20: Telefon | G20: Kabát | H20: Kölcsön | I20: Verseny
A21: rsz-006 | B21: 2026-09-28 | C21: 4 | D21: Amit meg lehet oldani | F21: Rejtvény | G21: Feladat | H21: Csomó | I21: Cipőfűző
A22: rsz-007 | B22: 2026-09-29 | C22: 1 | D22: Madarak | F22: Gólya | G22: Fecske | H22: Bagoly | I22: Pinty
A23: rsz-007 | B23: 2026-09-29 | C23: 2 | D23: ___ + KÖNYV | F23: Tan | G23: Szak | H23: Mese | I23: Zseb
A24: rsz-007 | B24: 2026-09-29 | C24: 3 | D24: Aminek füle van | F24: Bögre | G24: Kosár | H24: Fazék | I24: Zsák
A25: rsz-007 | B25: 2026-09-29 | C25: 4 | D25: Pénznemek, amik mást is jelentenek | F25: Font | G25: Márka | H25: Korona | I25: Frank
A26: rsz-008 | B26: 2026-09-30 | C26: 1 | D26: Gombák | F26: Vargánya | G26: Csiperke | H26: Galóca | I26: Rizike
A27: rsz-008 | B27: 2026-09-30 | C27: 2 | D27: Balatoni települések | F27: Tihany | G27: Siófok | H27: Fonyód | I27: Keszthely
A28: rsz-008 | B28: 2026-09-30 | C28: 3 | D28: Amit el lehet kapni | F28: Labda | G28: Nátha | H28: Fonál | I28: Tolvaj
A29: rsz-008 | B29: 2026-09-30 | C29: 4 | D29: Magyar városok anagrammái | E29: Eger, Gyula, Makó, Szeged | F29: Rege | G29: Gulya | H29: Kóma | I29: Degesz
A30: rsz-009 | B30: 2026-10-01 | C30: 1 | D30: Fűszerek | F30: Kapor | G30: Bors | H30: Kömény | I30: Babér
A31: rsz-009 | B31: 2026-10-01 | C31: 2 | D31: SZÉL + ___ | F31: Csend | G31: Vihar | H31: Kakas | I31: Malom
A32: rsz-009 | B32: 2026-10-01 | C32: 3 | D32: Oda-vissza ugyanaz | F32: Görög | G32: Kerek | H32: Pap | I32: Sas
A33: rsz-009 | B33: 2026-10-01 | C33: 4 | D33: ___ + LÁB | F33: Szék | G33: Asztal | H33: Kamat | I33: Gólya
A34: rsz-010 | B34: 2026-10-02 | C34: 1 | D34: Magyar sajtok | F34: Trappista | G34: Pannónia | H34: Óvári | I34: Karaván
A35: rsz-010 | B35: 2026-10-02 | C35: 2 | D35: SZEM + ___ | F35: Üveg | G35: Héj | H35: Golyó | I35: Tanú
A36: rsz-010 | B36: 2026-10-02 | C36: 3 | D36: Amit be lehet tartani | F36: Szó | G36: Ígéret | H36: Szabály | I36: Távolság
A37: rsz-010 | B37: 2026-10-02 | C37: 4 | D37: Városok, amik köznevek is | F37: Tata | G37: Baja | H37: Gyula | I37: Hajós
A38: rsz-011 | B38: 2026-10-03 | C38: 1 | D38: Budapesti metrómegállók | F38: Astoria | G38: Blaha | H38: Opera | I38: Lehel
A39: rsz-011 | B39: 2026-10-03 | C39: 2 | D39: Magyar kártyajátékok | F39: Ulti | G39: Römi | H39: Makaó | I39: Snapszer
A40: rsz-011 | B40: 2026-10-03 | C40: 3 | D40: Amit fel lehet állítani | F40: Rekord | G40: Sátor | H40: Csapat | I40: Szobor
...

Sheet Segéd
A1: feladvany_id | B1: pozicio | C1: szo | E1: id_lista
A2: rsz-002 | B2: 1 | C2: Jókai | E2: rsz-002
A3: rsz-002 | B3: 2 | C3: Eskü | E3: rsz-003
A4: rsz-002 | B4: 3 | C4: Halász | E4: rsz-004
A5: rsz-002 | B5: 4 | C5: Szabó | E5: rsz-005
A6: rsz-002 | B6: 5 | C6: Fegyver | E6: rsz-006
A7: rsz-002 | B7: 6 | C7: Lánc | E7: rsz-007
A8: rsz-002 | B8: 7 | C8: Újházi | E8: rsz-008
A9: rsz-002 | B9: 8 | C9: Vizsga | E9: rsz-009
A10: rsz-002 | B10: 9 | C10: Erzsébet | E10: rsz-010
A11: rsz-002 | B11: 10 | C11: Szabadság | E11: rsz-011
A12: rsz-002 | B12: 11 | C12: Molnár | E12: rsz-012
A13: rsz-002 | B13: 12 | C13: Gulyás | E13: rsz-013
... A43: rsz-004 | B43: 10 | C43: Esterházy | E43: rsz-042
A44: rsz-004 | B44: 11 | C44: Puska
A45: rsz-004 | B45: 12 | C45: Kökény
A46: rsz-004 | B46: 13 | C46: Dobos
A47: rsz-004 | B47: 14 | C47: Vicc
A48: rsz-004 | B48: 15 | C48: Tök
A49: rsz-004 | B49: 16 | C49: Szilva
A50: rsz-005 | B50: 1 | C50: Homok
A51: rsz-005 | B51: 2 | C51: Frakk
A52: rsz-005 | B52: 3 | C52: Katapult
A53: rsz-005 | B53: 4 | C53: Ferences
A54: rsz-005 | B54: 5 | C54: Lát
A55: rsz-005 | B55: 6 | C55: Vuk
... A673: rsz-042 | B673: 16 | C673: Gén

Sheet Játék
A1: Rokonszavak – gyakorlólap
A2: Válassz feladványt: | B2: rsz-033 | C2: =VLOOKUP(B2,Feladványok!A:B,2,FALSE())
A4: Keresd meg a négy négyes csoportot:
A6: =INDEX(Segéd!$C$2:$C$673,MATCH($B$2,Segéd!$A$2:$A$673,0)+1-1) | B6: =INDEX(Segéd!$C$2:$C$673,MATCH($B$2,Segéd!$A$2:$A$673,0)+2-1) | C6: =INDEX(Segéd!$C$2:$C$673,MATCH($B$2,Segéd!$A$2:$A$673,0)+3-1) | D6: =INDEX(Segéd!$C$2:$C$673,MATCH($B$2,Segéd!$A$2:$A$673,0)+4-1)
A7: =INDEX(Segéd!$C$2:$C$673,MATCH($B$2,Segéd!$A$2:$A$673,0)+5-1) | B7: =INDEX(Segéd!$C$2:$C$673,MATCH($B$2,Segéd!$A$2:$A$673,0)+6-1) | C7: =INDEX(Segéd!$C$2:$C$673,MATCH($B$2,Segéd!$A$2:$A$673,0)+7-1) | D7: =INDEX(Segéd!$C$2:$C$673,MATCH($B$2,Segéd!$A$2:$A$673,0)+8-1)
A8: =INDEX(Segéd!$C$2:$C$673,MATCH($B$2,Segéd!$A$2:$A$673,0)+9-1) | B8: =INDEX(Segéd!$C$2:$C$673,MATCH($B$2,Segéd!$A$2:$A$673,0)+10-1) | C8: =INDEX(Segéd!$C$2:$C$673,MATCH($B$2,Segéd!$A$2:$A$673,0)+11-1) | D8: =INDEX(Segéd!$C$2:$C$673,MATCH($B$2,Segéd!$A$2:$A$673,0)+12-1)
A9: =INDEX(Segéd!$C$2:$C$673,MATCH($B$2,Segéd!$A$2:$A$673,0)+13-1) | B9: =INDEX(Segéd!$C$2:$C$673,MATCH($B$2,Segéd!$A$2:$A$673,0)+14-1) | C9: =INDEX(Segéd!$C$2:$C$673,MATCH($B$2,Segéd!$A$2:$A$673,0)+15-1) | D9: =INDEX(Segéd!$C$2:$C$673,MATCH($B$2,Segéd!$A$2:$A$673,0)+16-1)
A20: MEGOLDÁS (görgess ide, ha kész vagy)
A22: Szint | B22: Kategória | C22: Szavak | G22: Megjegyzés
A23: 1 | B23: =INDEX(Feladványok!$D$2:$D$169,MATCH($B$2,Feladványok!$A$2:$A$169,0)+1-1) | C23: =INDEX(Feladványok!$F$2:$F$169,MATCH($B$2,Feladványok!$A$2:$A$169,0)+1-1) | D23: =INDEX(Feladványok!$G$2:$G$169,MATCH($B$2,Feladványok!$A$2:$A$169,0)+1-1) | E23: =INDEX(Feladványok!$H$2:$H$169,MATCH($B$2,Feladványok!$A$2:$A$169,0)+1-1) | F23: =INDEX(Feladványok!$I$2:$I$169,MATCH($B$2,Feladványok!$A$2:$A$169,0)+1-1) | G23: =IF(INDEX(Feladványok!$E$2:$E$169,MATCH($B$2,Feladványok!$A$2:$A$169,0)+1-1)="","",INDEX(Feladványok!$E$2:$E$169,MATCH($B$2,Feladványok!$A$2:$A$169,0)+1-1))
A24: 2 | B24: =INDEX(Feladványok!$D$2:$D$169,MATCH($B$2,Feladványok!$A$2:$A$169,0)+2-1) | C24: =INDEX(Feladványok!$F$2:$F$169,MATCH($B$2,Feladványok!$A$2:$A$169,0)+2-1) | D24: =INDEX(Feladványok!$G$2:$G$169,MATCH($B$2,Feladványok!$A$2:$A$169,0)+2-1) | E24: =INDEX(Feladványok!$H$2:$H$169,MATCH($B$2,Feladványok!$A$2:$A$169,0)+2-1) | F24: =INDEX(Feladványok!$I$2:$I$169,MATCH($B$2,Feladványok!$A$2:$A$169,0)+2-1) | G24: =IF(INDEX(Feladványok!$E$2:$E$169,MATCH($B$2,Feladványok!$A$2:$A$169,0)+2-1)="","",INDEX(Feladványok!$E$2:$E$169,MATCH($B$2,Feladványok!$A$2:$A$169,0)+2-1))
A25: 3 | B25: =INDEX(Feladványok!$D$2:$D$169,MATCH($B$2,Feladványok!$A$2:$A$169,0)+3-1) | C25: =INDEX(Feladványok!$F$2:$F$169,MATCH($B$2,Feladványok!$A$2:$A$169,0)+3-1) | D25: =INDEX(Feladványok!$G$2:$G$169,MATCH($B$2,Feladványok!$A$2:$A$169,0)+3-1) | E25: =INDEX(Feladványok!$H$2:$H$169,MATCH($B$2,Feladványok!$A$2:$A$169,0)+3-1) | F25: =INDEX(Feladványok!$I$2:$I$169,MATCH($B$2,Feladványok!$A$2:$A$169,0)+3-1) | G25: =IF(INDEX(Feladványok!$E$2:$E$169,MATCH($B$2,Feladványok!$A$2:$A$169,0)+3-1)="","",INDEX(Feladványok!$E$2:$E$169,MATCH($B$2,Feladványok!$A$2:$A$169,0)+3-1))
A26: 4 | B26: =INDEX(Feladványok!$D$2:$D$169,MATCH($B$2,Feladványok!$A$2:$A$169,0)+4-1) | C26: =INDEX(Feladványok!$F$2:$F$169,MATCH($B$2,Feladványok!$A$2:$A$169,0)+4-1) | D26: =INDEX(Feladványok!$G$2:$G$169,MATCH($B$2,Feladványok!$A$2:$A$169,0)+4-1) | E26: =INDEX(Feladványok!$H$2:$H$169,MATCH($B$2,Feladványok!$A$2:$A$169,0)+4-1) | F26: =INDEX(Feladványok!$I$2:$I$169,MATCH($B$2,Feladványok!$A$2:$A$169,0)+4-1) | G26: =IF(INDEX(Feladványok!$E$2:$E$169,MATCH($B$2,Feladványok!$A$2:$A$169,0)+4-1)="","",INDEX(Feladványok!$E$2:$E$169,MATCH($B$2,Feladványok!$A$2:$A$169,0)+4-1))
